Workbook

Sheet README
A1: Public lab reports meet quick-commerce demand: MVP product list
A2: Built 2 Oct 2026 for the Food Quality Rater MVP. Everything here was read from public web pages on that date. I did not open lab PDFs, buy products or run any test.
A4: What this is
A5: Purpose | B5: A starting list for the MVP: Indian packaged-food and nutrition products whose lab test reports (or lab-backed ratings) are publicly listed, checked against Blinkit, Zepto, Instamart and BigBasket so you can start with products people actually buy.
A6: Where to look first | B6: Shortlist: one row per quick-commerce (QC) product line I checked, ranked by QC score. All reports: every report row from four public sources, filterable. QC listings: the listing links and ratings counts behind every platform flag. QC signals: published data on what sells on QC. Report hubs: where each source keeps its reports and what the terms look like. Scoring: every weight and threshold. Blue cells are editable and everything recalculates.
A7: What the data shows | B7: Trustified is not only supplements. Its list includes mainstream staples and snacks that sell heavily on QC: Amul, Mother Dairy and Country Delight milk, Aashirvaad atta, Tata Salt, MDH and Everest masalas, Kellogg's, Cadbury, Lindt and Amul chocolate, Haldiram's. Many of those carry a Failed verdict, which is where a Trust Report matters most and where the PRD's publication gate applies.
A9: Key numbers (live formulas)
A10: Report rows | B10: =COUNTA('All reports'!$A$5:$A$249) -> 245
A11: from Trustified Pass/Fail | B11: =COUNTIF('All reports'!$J$5:$J$249,"Trustified Pass/Fail") -> 179
A12: from Trustified NMR (honey) | B12: =COUNTIF('All reports'!$J$5:$J$249,"Trustified NMR") -> 6
A13: from The Whole Truth's hub | B13: =COUNTIF('All reports'!$J$5:$J$249,"The Whole Truth hub") -> 6
A14: from Unbox Health | B14: =COUNTIF('All reports'!$J$5:$J$249,"Unbox Health") -> 54
A15: Rows marked Passed | B15: =COUNTIF('All reports'!$F$5:$F$249,"Passed") -> 100
A16: Rows marked Failed | B16: =COUNTIF('All reports'!$F$5:$F$249,"Failed") -> 56
A17: Rows marked Expired (incl. Unbox) | B17: =COUNTIF('All reports'!$F$5:$F$249,"Expired") -> 34
A18: Rows on a QC product line I checked | B18: =SUMPRODUCT(--('All reports'!$M$5:$M$249<>"")) -> 50
A19: QC product lines checked | B19: =COUNTIF('All reports'!$Z$5:$Z$249,1) -> 39
A20: of which listed on 3 or more platforms | B20: =COUNTIFS('All reports'!$Z$5:$Z$249,1,'All reports'!$S$5:$S$249,">=3") -> 21
A21: of which the latest report is a Fail | B21: =COUNTIFS('All reports'!$Z$5:$Z$249,1,'All reports'!$F$5:$F$249,"Failed") -> 12
A22: Highest ratings count seen on a listing | B22: =MAX('All reports'!$T$5:$T$249) -> 1581833
A23: Maximum possible QC score at current weights | B23: =Scoring!B19 -> 14
A25: How the QC score works
A26: Formula | B26: QC score = (confirmed platforms x 1 + demand tier x 2) x match factor + 2 if the category is a QC top-seller category + freshness points. Freshness: 2 if the report is under 12 months old, 1 if 12-24 months, 0 if older, 1 if undated, 0 if Expired. Maximum 14 at the default weights. The verdict does not change the score, so a failing product on a best-selling line ranks high on purpose.
A27: Platform flags (Blinkit to BigBasket) | B27: Y = a listing page or brand page seen on 2 Oct 2026. ? = only a third-party or cached page; not scored. - = not seen in my checks (not proof it is not sold). Blank = line not checked.
A28: QC match | B28: Exact = same product as the tested sample, pack size aside. Same line = same brand line, tested SKU not confirmed on the listing. Variant differs = the brand line is listed but it is a different variant from the one tested. Factors are 1, 0.75 and 0.5.
A29: Top ratings count | B29: The highest ratings count on any listing of that line. Cumulative and pooled across packs and pincodes. It is a popularity proxy, not a sales rank; QC apps publish no rank. n/c = no ratings count captured on any listing of that line.
A30: Primary for line | B30: 1 marks the row that stands for its QC line on the Shortlist: the most recently dated report, first row on a tie. Other rows for the line stay in All reports.
A31: Verdict | B31: Trustified's own label (Passed, Failed, Expired, Not recommended; 'No status shown' where the tile has none). 'Report published' means a lab report is public but carries no verdict (Trustified NMR honey tests, The Whole Truth's hub). Unbox rows: Rated = current grade, Expired = shown as Previously Rated, Listed, rating not captured = on Unbox but the grade was not captured.
A33: Method
A34: 1. Reports | B34: Read Trustified's public Pass/Fail list, category pages and NMR page, The Whole Truth's batch hub, and Unbox Health's explore pages (grades are visible without login, full reports are not).
A35: 2. QC check | B35: For lab-tested products that looked like likely sellers, I searched Blinkit, Zepto, Instamart and BigBasket listing pages and recorded the listing, pack, price, ratings count and URL on QC listings. The check covers only the lines in the Shortlist.
A36: 3. Best-seller proxy | B36: QC platforms publish no sales ranks. I used ratings counts on product pages as a popularity proxy and published category rankings (QC signals) to flag top categories.
A37: 4. Not done | B37: No lab report was re-verified. Pack size or SKU code, lab accreditation, parameters tested and the reason for any Fail are not captured: they sit inside each report. Trustified and Whole Truth rows are batch-level lab evidence; Unbox rows are a competitor's grade for a bought sample.
A39: Caveats
A40: 1. Coverage | B40: QC columns are filled only for the lines checked; blank means not checked. Not yet checked (search rate limit): Daawat Brown Rice, Everest Garam Masala, Epigamia Turbo, Patanjali Cow Ghee and Amul Cheese Cubes.
A41: 2. Older Trustified entries | B41: Trustified's list continues with about 85 older entries (the ones I sampled are 2023-24 and mostly Expired). I left them out on purpose, so this is not the full Trustified archive.
A42: 3. Snapshot | B42: Listings, prices and ratings were read on 2 Oct 2026 without a delivery pincode. Availability varies by pincode and changes daily. Zepto and Blinkit pages sometimes show a different pack or variant; QC match and the notes say where.
A43: 4. Reuse terms | B43: Trustified shows no API or reuse terms. Showing its report content inside the product needs written permission; linking out is the safe default (PRD critical path). Unbox is a direct competitor and gates reports behind a login. Whole Truth reports are the brand's own PDFs; ask before reusing.
A44: 5. Reports are per batch | B44: A report covers one batch of one SKU. A Pass on one batch is not a verdict on the line. Failed and Not recommended rows need the PRD publication gate (legal check, brand notice, 7-day reply) before anything is shown.
A45: 6. Data quirks | B45: Three Trustified rows (Farmley Makhana, Noto, Minus 30) carry Jan 2025 publish dates that look earlier than their batch codes imply. MuscleBlaze Iso Zero, MuscleBlaze Performance Whey, Nutrabay Concentrate Whey and As It Is Atom Creatine show no batch or date on the list page. Gritzo age bands read '13 years' on Trustified. A '6.6 lac' ratings card on Blinkit (Amul Masti pouch curd) is read as 660,000.
...

Sheet Shortlist
A1: Shortlist: quick-commerce product lines with a public lab report, ranked by QC score
A2: One row per product line I checked on Blinkit, Zepto, Instamart and BigBasket. Each line is represented by its most recent dated report. Weights and thresholds: Scoring sheet. Verdicts do not change the rank.
A4: QC rank | B4: Brand | C4: Product (as listed by the report source) | D4: Category | E4: Verdict | F4: Report date | G4: Lab | H4: Batch tested | I4: Source | J4: Platforms with a listing | K4: Top ratings count | L4: Demand tier (0-3) | M4: QC score | N4: QC match | O4: Other report rows for this line | P4: Report | Q4: QC listing | R4: Publish route | S4: Helper: row in All reports
A5: 1 | B5: =IF($S5="","",INDEX('All reports'!$B$5:$B$249,$S5)) -> Mother Dairy | C5: =IF($S5="","",INDEX('All reports'!$C$5:$C$249,$S5)) -> Cow Milk | D5: =IF($S5="","",INDEX('All reports'!$E$5:$E$249,$S5)) -> Milk | E5: =IF($S5="","",INDEX('All reports'!$F$5:$F$249,$S5)) -> Failed | F5: =IF($S5="","",IF(INDEX('All reports'!$G$5:$G$249,$S5)="","",INDEX('All reports'!$G$5:$G$249,$S5))) -> 46061 | G5: =IF($S5="","",INDEX('All reports'!$I$5:$I$249,$S5)) -> Eurofins | H5: =IF($S5="","",IF(INDEX('All reports'!$H$5:$H$249,$S5)="","",INDEX('All reports'!$H$5:$H$249,$S5))) -> (05)05NOV25SZ5M | I5: =IF($S5="","",INDEX('All reports'!$J$5:$J$249,$S5)) -> Trustified Pass/Fail | J5: =IF($S5="","",SUBSTITUTE(TRIM(IF(INDEX('All reports'!$O$5:$O$249,$S5)="Y","Blinkit",IF(INDEX('All reports'!$O$5:$O$249,$S5)="?","Blinkit?",""))&" "&IF(INDEX('All reports'!$P$5:$P$249,$S5)="Y","Zepto",IF(INDEX('All reports'!$P$5:$P$249,$S5)="?","Zepto?",""))&" "&IF(INDEX('All reports'!$Q$5:$Q$249,$S5)="Y","Instamart",IF(INDEX('All reports'!$Q$5:$Q$249,$S5)="?","Instamart?",""))&" "&IF(INDEX('All reports'!$R$5:$R$249,$S5)="Y","BigBasket",IF(INDEX('All reports'!$R$5:$R$249,$S5)="?","BigBasket?","")))," "," · ")) -> Blinkit · Zepto · Instamart · BigBasket | K5: =IF($S5="","",INDEX('All reports'!$T$5:$T$249,$S5)) -> 302321 | L5: =IF($S5="","",INDEX('All reports'!$U$5:$U$249,$S5)) -> 3 | M5: =IF($S5="","",INDEX('All reports'!$Y$5:$Y$249,$S5)) -> 14 | N5: =IF($S5="","",IF(INDEX('All reports'!$N$5:$N$249,$S5)="","",INDEX('All reports'!$N$5:$N$249,$S5))) -> Exact | O5: =IF($S5="","",COUNTIF('All reports'!$M$5:$M$249,INDEX('All reports'!$M$5:$M$249,$S5))-1) -> 0 | P5: =IFERROR(HYPERLINK(INDEX('All reports'!$L$5:$L$249,$S5),"Open report"),"") -> Open report | Q5: =IFERROR(HYPERLINK(INDEX('QC listings'!$H$5:$H$200,MATCH(INDEX('All reports'!$M$5:$M$249,$S5),'QC listings'!$A$5:$A$200,0)),"Open listing"),"") -> Open listing | R5: =IF($S5="","",INDEX('All reports'!$AC$5:$AC$249,$S5)) -> Link out; licence needed to display; run the PRD publication gate first (negative verdict) | S5: =IFERROR(MATCH($A5,'All reports'!$AA$5:$AA$249,0),"") -> 5
A6: 2 | B6: =IF($S6="","",INDEX('All reports'!$B$5:$B$249,$S6)) -> Amul | C6: =IF($S6="","",INDEX('All reports'!$C$5:$C$249,$S6)) -> Gold Milk | D6: =IF($S6="","",INDEX('All reports'!$E$5:$E$249,$S6)) -> Milk | E6: =IF($S6="","",INDEX('All reports'!$F$5:$F$249,$S6)) -> Failed | F6: =IF($S6="","",IF(INDEX('All reports'!$G$5:$G$249,$S6)="","",INDEX('All reports'!$G$5:$G$249,$S6))) -> 46061 | G6: =IF($S6="","",INDEX('All reports'!$I$5:$I$249,$S6)) -> Eurofins | H6: =IF($S6="","",IF(INDEX('All reports'!$H$5:$H$249,$S6)="","",INDEX('All reports'!$H$5:$H$249,$S6))) -> SR26DM | I6: =IF($S6="","",INDEX('All reports'!$J$5:$J$249,$S6)) -> Trustified Pass/Fail | J6: =IF($S6="","",SUBSTITUTE(TRIM(IF(INDEX('All reports'!$O$5:$O$249,$S6)="Y","Blinkit",IF(INDEX('All reports'!$O$5:$O$249,$S6)="?","Blinkit?",""))&" "&IF(INDEX('All reports'!$P$5:$P$249,$S6)="Y","Zepto",IF(INDEX('All reports'!$P$5:$P$249,$S6)="?","Zepto?",""))&" "&IF(INDEX('All reports'!$Q$5:$Q$249,$S6)="Y","Instamart",IF(INDEX('All reports'!$Q$5:$Q$249,$S6)="?","Instamart?",""))&" "&IF(INDEX('All reports'!$R$5:$R$249,$S6)="Y","BigBasket",IF(INDEX('All reports'!$R$5:$R$249,$S6)="?","BigBasket?","")))," "," · ")) -> Blinkit · Zepto · BigBasket | K6: =IF($S6="","",INDEX('All reports'!$T$5:$T$249,$S6)) -> 1581833 | L6: =IF($S6="","",INDEX('All reports'!$U$5:$U$249,$S6)) -> 3 | M6: =IF($S6="","",INDEX('All reports'!$Y$5:$Y$249,$S6)) -> 13 | N6: =IF($S6="","",IF(INDEX('All reports'!$N$5:$N$249,$S6)="","",INDEX('All reports'!$N$5:$N$249,$S6))) -> Exact | O6: =IF($S6="","",COUNTIF('All reports'!$M$5:$M$249,INDEX('All reports'!$M$5:$M$249,$S6))-1) -> 0 | P6: =IFERROR(HYPERLINK(INDEX('All reports'!$L$5:$L$249,$S6),"Open report"),"") -> Open report | Q6: =IFERROR(HYPERLINK(INDEX('QC listings'!$H$5:$H$200,MATCH(INDEX('All reports'!$M$5:$M$249,$S6),'QC listings'!$A$5:$A$200,0)),"Open listing"),"") -> Open listing | R6: =IF($S6="","",INDEX('All reports'!$AC$5:$AC$249,$S6)) -> Link out; licence needed to display; run the PRD publication gate first (negative verdict) | S6: =IFERROR(MATCH($A6,'All reports'!$AA$5:$AA$249,0),"") -> 1
A7: 3 | B7: =IF($S7="","",INDEX('All reports'!$B$5:$B$249,$S7)) -> Amul | C7: =IF($S7="","",INDEX('All reports'!$C$5:$C$249,$S7)) -> Taaza Homogenised Toned Milk | D7: =IF($S7="","",INDEX('All reports'!$E$5:$E$249,$S7)) -> Milk | E7: =IF($S7="","",INDEX('All reports'!$F$5:$F$249,$S7)) -> Passed | F7: =IF($S7="","",IF(INDEX('All reports'!$G$5:$G$249,$S7)="","",INDEX('All reports'!$G$5:$G$249,$S7))) -> 46061 | G7: =IF($S7="","",INDEX('All reports'!$I$5:$I$249,$S7)) -> Eurofins | H7: =IF($S7="","",IF(INDEX('All reports'!$H$5:$H$249,$S7)="","",INDEX('All reports'!$H$5:$H$249,$S7))) -> MAC2691 | I7: =IF($S7="","",INDEX('All reports'!$J$5:$J$249,$S7)) -> Trustified Pass/Fail | J7: =IF($S7="","",SUBSTITUTE(TRIM(IF(INDEX('All reports'!$O$5:$O$249,$S7)="Y","Blinkit",IF(INDEX('All reports'!$O$5:$O$249,$S7)="?","Blinkit?",""))&" "&IF(INDEX('All reports'!$P$5:$P$249,$S7)="Y","Zepto",IF(INDEX('All reports'!$P$5:$P$249,$S7)="?","Zepto?",""))&" "&IF(INDEX('All reports'!$Q$5:$Q$249,$S7)="Y","Instamart",IF(INDEX('All reports'!$Q$5:$Q$249,$S7)="?","Instamart?",""))&" "&IF(INDEX('All reports'!$R$5:$R$249,$S7)="Y","BigBasket",IF(INDEX('All reports'!$R$5:$R$249,$S7)="?","BigBasket?","")))," "," · ")) -> Blinkit · Zepto · BigBasket | K7: =IF($S7="","",INDEX('All reports'!$T$5:$T$249,$S7)) -> 1214721 | L7: =IF($S7="","",INDEX('All reports'!$U$5:$U$249,$S7)) -> 3 | M7: =IF($S7="","",INDEX('All reports'!$Y$5:$Y$249,$S7)) -> 13 | N7: =IF($S7="","",IF(INDEX('All reports'!$N$5:$N$249,$S7)="","",INDEX('All reports'!$N$5:$N$249,$S7))) -> Exact | O7: =IF($S7="","",COUNTIF('All reports'!$M$5:$M$249,INDEX('All reports'!$M$5:$M$249,$S7))-1) -> 0 | P7: =IFERROR(HYPERLINK(INDEX('All reports'!$L$5:$L$249,$S7),"Open report"),"") -> Open report | Q7: =IFERROR(HYPERLINK(INDEX('QC listings'!$H$5:$H$200,MATCH(INDEX('All reports'!$M$5:$M$249,$S7),'QC listings'!$A$5:$A$200,0)),"Open listing"),"") -> Open listing | R7: =IF($S7="","",INDEX('All reports'!$AC$5:$AC$249,$S7)) -> Link out; Trustified's written licence needed to display the report | S7: =IFERROR(MATCH($A7,'All reports'!$AA$5:$AA$249,0),"") -> 2
A8: 4 | B8: =IF($S8="","",INDEX('All reports'!$B$5:$B$249,$S8)) -> Amul | C8: =IF($S8="","",INDEX('All reports'!$C$5:$C$249,$S8)) -> Masti Dahi Cup | D8: =IF($S8="","",INDEX('All reports'!$E$5:$E$249,$S8)) -> Curd & yoghurt | E8: =IF($S8="","",INDEX('All reports'!$F$5:$F$249,$S8)) -> Passed | F8: =IF($S8="","",IF(INDEX('All reports'!$G$5:$G$249,$S8)="","",INDEX('All reports'!$G$5:$G$249,$S8))) -> 46026 | G8: =IF($S8="","",INDEX('All reports'!$I$5:$I$249,$S8)) -> Eurofins | H8: =IF($S8="","",IF(INDEX('All reports'!$H$5:$H$249,$S8)="","",INDEX('All reports'!$H$5:$H$249,$S8))) -> MPC 338/01 | I8: =IF($S8="","",INDEX('All reports'!$J$5:$J$249,$S8)) -> Trustified Pass/Fail | J8: =IF($S8="","",SUBSTITUTE(TRIM(IF(INDEX('All reports'!$O$5:$O$249,$S8)="Y","Blinkit",IF(INDEX('All reports'!$O$5:$O$249,$S8)="?","Blinkit?",""))&" "&IF(INDEX('All reports'!$P$5:$P$249,$S8)="Y","Zepto",IF(INDEX('All reports'!$P$5:$P$249,$S8)="?","Zepto?",""))&" "&IF(INDEX('All reports'!$Q$5:$Q$249,$S8)="Y","Instamart",IF(INDEX('All reports'!$Q$5:$Q$249,$S8)="?","Instamart?",""))&" "&IF(INDEX('All reports'!$R$5:$R$249,$S8)="Y","BigBasket",IF(INDEX('All reports'!$R$5:$R$249,$S8)="?","BigBasket?","")))," "," · ")) -> Zepto · BigBasket | K8: =IF($S8="","",INDEX('All reports'!$T$5:$T$249,$S8)) -> 103152 | L8: =IF($S8="","",INDEX('All reports'!$U$5:$U$249,$S8)) -> 3 | M8: =IF($S8="","",INDEX('All reports'!$Y$5:$Y$249,$S8)) -> 12 | N8: =IF($S8="","",IF(INDEX('All reports'!$N$5:$N$249,$S8)="","",INDEX('All reports'!$N$5:$N$249,$S8))) -> Exact | O8: =IF($S8="","",COUNTIF('All reports'!$M$5:$M$249,INDEX('All reports'!$M$5:$M$249,$S8))-1) -> 0 | P8: =IFERROR(HYPERLINK(INDEX('All reports'!$L$5:$L$249,$S8),"Open report"),"") -> Open report | Q8: =IFERROR(HYPERLINK(INDEX('QC listings'!$H$5:$H$200,MATCH(INDEX('All reports'!$M$5:$M$249,$S8),'QC listings'!$A$5:$A$200,0)),"Open listing"),"") -> Open listing | R8: =IF($S8="","",INDEX('All reports'!$AC$5:$AC$249,$S8)) -> Link out; Trustified's written licence needed to display the report | S8: =IFERROR(MATCH($A8,'All reports'!$AA$5:$AA$249,0),"") -> 7
A9: 5 | B9: =IF($S9="","",INDEX('All reports'!$B$5:$B$249,$S9)) -> Amul | C9: =IF($S9="","",INDEX('All reports'!$C$5:$C$249,$S9)) -> Masti Dahi | D9: =IF($S9="","",INDEX('All reports'!$E$5:$E$249,$S9)) -> Curd & yoghurt | E9: =IF($S9="","",INDEX('All reports'!$F$5:$F$249,$S9)) -> Failed | F9: =IF($S9="","",IF(INDEX('All reports'!$G$5:$G$249,$S9)="","",INDEX('All reports'!$G$5:$G$249,$S9))) -> 46026 | G9: =IF($S9="","",INDEX('All reports'!$I$5:$I$249,$S9)) -> Eurofins | H9: =IF($S9="","",IF(INDEX('All reports'!$H$5:$H$249,$S9)="","",INDEX('All reports'!$H$5:$H$249,$S9))) -> SR04CM | I9: =IF($S9="","",INDEX('All reports'!$J$5:$J$249,$S9)) -> Trustified Pass/Fail | J9: =IF($S9="","",SUBSTITUTE(TRIM(IF(INDEX('All reports'!$O$5:$O$249,$S9)="Y","Blinkit",IF(INDEX('All reports'!$O$5:$O$249,$S9)="?","Blinkit?",""))&" "&IF(INDEX('All reports'!$P$5:$P$249,$S9)="Y","Zepto",IF(INDEX('All reports'!$P$5:$P$249,$S9)="?","Zepto?",""))&" "&IF(INDEX('All reports'!$Q$5:$Q$249,$S9)="Y","Instamart",IF(INDEX('All reports'!$Q$5:$Q$249,$S9)="?","Instamart?",""))&" "&IF(INDEX('All reports'!$R$5:$R$249,$S9)="Y","BigBasket",IF(INDEX('All reports'!$R$5:$R$249,$S9)="?","BigBasket?","")))," "," · ")) -> Blinkit | K9: =IF($S9="","",INDEX('All reports'!$T$5:$T$249,$S9)) -> 660000 | L9: =IF($S9="","",INDEX('All reports'!$U$5:$U$249,$S9)) -> 3 | M9: =IF($S9="","",INDEX('All reports'!$Y$5:$Y$249,$S9)) -> 11 | N9: =IF($S9="","",IF(INDEX('All reports'!$N$5:$N$249,$S9)="","",INDEX('All reports'!$N$5:$N$249,$S9))) -> Exact | O9: =IF($S9="","",COUNTIF('All reports'!$M$5:$M$249,INDEX('All reports'!$M$5:$M$249,$S9))-1) -> 0 | P9: =IFERROR(HYPERLINK(INDEX('All reports'!$L$5:$L$249,$S9),"Open report"),"") -> Open report | Q9: =IFERROR(HYPERLINK(INDEX('QC listings'!$H$5:$H$200,MATCH(INDEX('All reports'!$M$5:$M$249,$S9),'QC listings'!$A$5:$A$200,0)),"Open listing"),"") -> Open listing | R9: =IF($S9="","",INDEX('All reports'!$AC$5:$AC$249,$S9)) -> Link out; licence needed to display; run the PRD publication gate first (negative verdict) | S9: =IFERROR(MATCH($A9,'All reports'!$AA$5:$AA$249,0),"") -> 6
A10: 6 | B10: =IF($S10="","",INDEX('All reports'!$B$5:$B$249,$S10)) -> Tata | C10: =IF($S10="","",INDEX('All reports'!$C$5:$C$249,$S10)) -> Tata Salt | D10: =IF($S10="","",INDEX('All reports'!$E$5:$E$249,$S10)) -> Atta, rice & salt | E10: =IF($S10="","",INDEX('All reports'!$F$5:$F$249,$S10)) -> Passed | F10: =IF($S10="","",IF(INDEX('All reports'!$G$5:$G$249,$S10)="","",INDEX('All reports'!$G$5:$G$249,$S10))) -> 45984 | G10: =IF($S10="","",INDEX('All reports'!$I$5:$I$249,$S10)) -> Eurofins | H10: =IF($S10="","",IF(INDEX('All reports'!$H$5:$H$249,$S10)="","",INDEX('All reports'!$H$5:$H$249,$S10))) -> PU | I10: =IF($S10="","",INDEX('All reports'!$J$5:$J$249,$S10)) -> Trustified Pass/Fail | J10: =IF($S10="","",SUBSTITUTE(TRIM(IF(INDEX('All reports'!$O$5:$O$249,$S10)="Y","Blinkit",IF(INDEX('All reports'!$O$5:$O$249,$S10)="?","Blinkit?",""))&" "&IF(INDEX('All reports'!$P$5:$P$249,$S10)="Y","Zepto",IF(INDEX('All reports'!$P$5:$P$249,$S10)="?","Zepto?",""))&" "&IF(INDEX('All reports'!$Q$5:$Q$249,$S10)="Y","Instamart",IF(INDEX('All reports'!$Q$5:$Q$249,$S10)="?","Instamart?",""))&" "&IF(INDEX('All reports'!$R$5:$R$249,$S10)="Y","BigBasket",IF(INDEX('All reports'!$R$5:$R$249,$S10)="?","BigBasket?","")))," "," · ")) -> Blinkit · Zepto · Instamart | K10: =IF($S10="","",INDEX('All reports'!$T$5:$T$249,$S10)) -> 496464 | L10: =IF($S10="","",INDEX('All reports'!$U$5:$U$249,$S10)) -> 3 | M10: =IF($S10="","",INDEX('All reports'!$Y$5:$Y$249,$S10)) -> 11 | N10: =IF($S10="","",IF(INDEX('All reports'!$N$5:$N$249,$S10)="","",INDEX('All reports'!$N$5:$N$249,$S10))) -> Exact | O10: =IF($S10="","",COUNTIF('All reports'!$M$5:$M$249,INDEX('All reports'!$M$5:$M$249,$S10))-1) -> 0 | P10: =IFERROR(HYPERLINK(INDEX('All reports'!$L$5:$L$249,$S10),"Open report"),"") -> Open report | Q10: =IFERROR(HYPERLINK(INDEX('QC listings'!$H$5:$H$200,MATCH(INDEX('All reports'!$M$5:$M$249,$S10),'QC listings'!$A$5:$A$200,0)),"Open listing"),"") -> Open listing | R10: =IF($S10="","",INDEX('All reports'!$AC$5:$AC$249,$S10)) -> Link out; Trustified's written licence needed to display the report | S10: =IFERROR(MATCH($A10,'All reports'!$AA$5:$AA$249,0),"") -> 36
A11: 7 | B11: =IF($S11="","",INDEX('All reports'!$B$5:$B$249,$S11)) -> Haldiram's | C11: =IF($S11="","",INDEX('All reports'!$C$5:$C$249,$S11)) -> Salted Peanuts | D11: =IF($S11="","",INDEX('All reports'!$E$5:$E$249,$S11)) -> Packaged snacks | E11: =IF($S11="","",INDEX('All reports'!$F$5:$F$249,$S11)) -> Passed | F11: =IF($S11="","",IF(INDEX('All reports'!$G$5:$G$249,$S11)="","",INDEX('All reports'!$G$5:$G$249,$S11))) -> 45764 | G11: =IF($S11="","",INDEX('All reports'!$I$5:$I$249,$S11)) -> Eurofins | H11: =IF($S11="","",IF(INDEX('All reports'!$H$5:$H$249,$S11)="","",INDEX('All reports'!$H$5:$H$249,$S11))) -> 24018 | I11: =IF($S11="","",INDEX('All reports'!$J$5:$J$249,$S11)) -> Trustified Pass/Fail | J11: =IF($S11="","",SUBSTITUTE(TRIM(IF(INDEX('All reports'!$O$5:$O$249,$S11)="Y","Blinkit",IF(INDEX('All reports'!$O$5:$O$249,$S11)="?","Blinkit?",""))&" "&IF(INDEX('All reports'!$P$5:$P$249,$S11)="Y","Zepto",IF(INDEX('All reports'!$P$5:$P$249,$S11)="?","Zepto?",""))&" "&IF(INDEX('All reports'!$Q$5:$Q$249,$S11)="Y","Instamart",IF(INDEX('All reports'!$Q$5:$Q$249,$S11)="?","Instamart?",""))&" "&IF(INDEX('All reports'!$R$5:$R$249,$S11)="Y","BigBasket",IF(INDEX('All reports'!$R$5:$R$249,$S11)="?","BigBasket?","")))," "," · ")) -> Blinkit · Zepto · Instamart · BigBasket | K11: =IF($S11="","",INDEX('All reports'!$T$5:$T$249,$S11)) -> 38843 | L11: =IF($S11="","",INDEX('All reports'!$U$5:$U$249,$S11)) -> 2 | M11: =IF($S11="","",INDEX('All reports'!$Y$5:$Y$249,$S11)) -> 11 | N11: =IF($S11="","",IF(INDEX('All reports'!$N$5:$N$249,$S11)="","",INDEX('All reports'!$N$5:$N$249,$S11))) -> Exact | O11: =IF($S11="","",COUNTIF('All reports'!$M$5:$M$249,INDEX('All reports'!$M$5:$M$249,$S11))-1) -> 0 | P11: =IFERROR(HYPERLINK(INDEX('All reports'!$L$5:$L$249,$S11),"Open report"),"") -> Open report | Q11: =IFERROR(HYPERLINK(INDEX('QC listings'!$H$5:$H$200,MATCH(INDEX('All reports'!$M$5:$M$249,$S11),'QC listings'!$A$5:$A$200,0)),"Open listing"),"") -> Open listing | R11: =IF($S11="","",INDEX('All reports'!$AC$5:$AC$249,$S11)) -> Link out; Trustified's written licence needed to display the report | S11: =IFERROR(MATCH($A11,'All reports'!$AA$5:$AA$249,0),"") -> 11
A12: 8 | B12: =IF($S12="","",INDEX('All reports'!$B$5:$B$249,$S12)) -> Country Delight | C12: =IF($S12="","",INDEX('All reports'!$C$5:$C$249,$S12)) -> Cow Milk | D12: =IF($S12="","",INDEX('All reports'!$E$5:$E$249,$S12)) -> Milk | E12: =IF($S12="","",INDEX('All reports'!$F$5:$F$249,$S12)) -> Failed | F12: =IF($S12="","",IF(INDEX('All reports'!$G$5:$G$249,$S12)="","",INDEX('All reports'!$G$5:$G$249,$S12))) -> 46061 | G12: =IF($S12="","",INDEX('All reports'!$I$5:$I$249,$S12)) -> Eurofins | H12: =IF($S12="","",IF(INDEX('All reports'!$H$5:$H$249,$S12)="","",INDEX('All reports'!$H$5:$H$249,$S12))) -> DJCMG | I12: =IF($S12="","",INDEX('All reports'!$J$5:$J$249,$S12)) -> Trustified Pass/Fail | J12: =IF($S12="","",SUBSTITUTE(TRIM(IF(INDEX('All reports'!$O$5:$O$249,$S12)="Y","Blinkit",IF(INDEX('All reports'!$O$5:$O$249,$S12)="?","Blinkit?",""))&" "&IF(INDEX('All reports'!$P$5:$P$249,$S12)="Y","Zepto",IF(INDEX('All reports'!$P$5:$P$249,$S12)="?","Zepto?",""))&" "&IF(INDEX('All reports'!$Q$5:$Q$249,$S12)="Y","Instamart",IF(INDEX('All reports'!$Q$5:$Q$249,$S12)="?","Instamart?",""))&" "&IF(INDEX('All reports'!$R$5:$R$249,$S12)="Y","BigBasket",IF(INDEX('All reports'!$R$5:$R$249,$S12)="?","BigBasket?","")))," "," · ")) -> Blinkit · Zepto · Instamart | K12: =IF($S12="","",INDEX('All reports'!$T$5:$T$249,$S12)) -> 13966 | L12: =IF($S12="","",INDEX('All reports'!$U$5:$U$249,$S12)) -> 2 | M12: =IF($S12="","",INDEX('All reports'!$Y$5:$Y$249,$S12)) -> 11 | N12: =IF($S12="","",IF(INDEX('All reports'!$N$5:$N$249,$S12)="","",INDEX('All reports'!$N$5:$N$249,$S12))) -> Exact | O12: =IF($S12="","",COUNTIF('All reports'!$M$5:$M$249,INDEX('All reports'!$M$5:$M$249,$S12))-1) -> 0 | P12: =IFERROR(HYPERLINK(INDEX('All reports'!$L$5:$L$249,$S12),"Open report"),"") -> Open report | Q12: =IFERROR(HYPERLINK(INDEX('QC listings'!$H$5:$H$200,MATCH(INDEX('All reports'!$M$5:$M$249,$S12),'QC listings'!$A$5:$A$200,0)),"Open listing"),"") -> Open listing | R12: =IF($S12="","",INDEX('All reports'!$AC$5:$AC$249,$S12)) -> Link out; licence needed to display; run the PRD publication gate first (negative verdict) | S12: =IFERROR(MATCH($A12,'All reports'!$AA$5:$AA$249,0),"") -> 4
A13: 9 | B13: =IF($S13="","",INDEX('All reports'!$B$5:$B$249,$S13)) -> Maggi | C13: =IF($S13="","",INDEX('All reports'!$C$5:$C$249,$S13)) -> Masala-ae-Magic | D13: =IF($S13="","",INDEX('All reports'!$E$5:$E$249,$S13)) -> Spices & masala | E13: =IF($S13="","",INDEX('All reports'!$F$5:$F$249,$S13)) -> Passed | F13: =IF($S13="","",IF(INDEX('All reports'!$G$5:$G$249,$S13)="","",INDEX('All reports'!$G$5:$G$249,$S13))) -> 46068 | G13: =IF($S13="","",INDEX('All reports'!$I$5:$I$249,$S13)) -> Eurofins | H13: =IF($S13="","",IF(INDEX('All reports'!$H$5:$H$249,$S13)="","",INDEX('All reports'!$H$5:$H$249,$S13))) -> 50580455AA-M | I13: =IF($S13="","",INDEX('All reports'!$J$5:$J$249,$S13)) -> Trustified Pass/Fail | J13: =IF($S13="","",SUBSTITUTE(TRIM(IF(INDEX('All reports'!$O$5:$O$249,$S13)="Y","Blinkit",IF(INDEX('All reports'!$O$5:$O$249,$S13)="?","Blinkit?",""))&" "&IF(INDEX('All reports'!$P$5:$P$249,$S13)="Y","Zepto",IF(INDEX('All reports'!$P$5:$P$249,$S13)="?","Zepto?",""))&" "&IF(INDEX('All reports'!$Q$5:$Q$249,$S13)="Y","Instamart",IF(INDEX('All reports'!$Q$5:$Q$249,$S13)="?","Instamart?",""))&" "&IF(INDEX('All reports'!$R$5:$R$249,$S13)="Y","BigBasket",IF(INDEX('All reports'!$R$5:$R$249,$S13)="?","BigBasket?","")))," "," · ")) -> Blinkit · Zepto · Instamart · BigBasket | K13: =IF($S13="","",INDEX('All reports'!$T$5:$T$249,$S13)) -> 94808 | L13: =IF($S13="","",INDEX('All reports'!$U$5:$U$249,$S13)) -> 2 | M13: =IF($S13="","",INDEX('All reports'!$Y$5:$Y$249,$S13)) -> 10 | N13: =IF($S13="","",IF(INDEX('All reports'!$N$5:$N$249,$S13)="","",INDEX('All reports'!$N$5:$N$249,$S13))) -> Exact | O13: =IF($S13="","",COUNTIF('All reports'!$M$5:$M$249,INDEX('All reports'!$M$5:$M$249,$S13))-1) -> 0 | P13: =IFERROR(HYPERLINK(INDEX('All reports'!$L$5:$L$249,$S13),"Open report"),"") -> Open report | Q13: =IFERROR(HYPERLINK(INDEX('QC listings'!$H$5:$H$200,MATCH(INDEX('All reports'!$M$5:$M$249,$S13),'QC listings'!$A$5:$A$200,0)),"Open listing"),"") -> Open listing | R13: =IF($S13="","",INDEX('All reports'!$AC$5:$AC$249,$S13)) -> Link out; Trustified's written licence needed to display the report | S13: =IFERROR(MATCH($A13,'All reports'!$AA$5:$AA$249,0),"") -> 50
A14: 10 | B14: =IF($S14="","",INDEX('All reports'!$B$5:$B$249,$S14)) -> Aashirvaad | C14: =IF($S14="","",INDEX('All reports'!$C$5:$C$249,$S14)) -> Superior MP Atta | D14: =IF($S14="","",INDEX('All reports'!$E$5:$E$249,$S14)) -> Atta, rice & salt | E14: =IF($S14="","",INDEX('All reports'!$F$5:$F$249,$S14)) -> Passed | F14: =IF($S14="","",IF(INDEX('All reports'!$G$5:$G$249,$S14)="","",INDEX('All reports'!$G$5:$G$249,$S14))) -> 46223 | G14: =IF($S14="","",INDEX('All reports'!$I$5:$I$249,$S14)) -> Eurofins | H14: =IF($S14="","",IF(INDEX('All reports'!$H$5:$H$249,$S14)="","",INDEX('All reports'!$H$5:$H$249,$S14))) -> 04A72904 | I14: =IF($S14="","",INDEX('All reports'!$J$5:$J$249,$S14)) -> Trustified Pass/Fail | J14: =IF($S14="","",SUBSTITUTE(TRIM(IF(INDEX('All reports'!$O$5:$O$249,$S14)="Y","Blinkit",IF(INDEX('All reports'!$O$5:$O$249,$S14)="?","Blinkit?",""))&" "&IF(INDEX('All reports'!$P$5:$P$249,$S14)="Y","Zepto",IF(INDEX('All reports'!$P$5:$P$249,$S14)="?","Zepto?",""))&" "&IF(INDEX('All reports'!$Q$5:$Q$249,$S14)="Y","Instamart",IF(INDEX('All reports'!$Q$5:$Q$249,$S14)="?","Instamart?",""))&" "&IF(INDEX('All reports'!$R$5:$R$249,$S14)="Y","BigBasket",IF(INDEX('All reports'!$R$5:$R$249,$S14)="?","BigBasket?","")))," "," · ")) -> Blinkit · Zepto · Instamart · BigBasket | K14: =IF($S14="","",INDEX('All reports'!$T$5:$T$249,$S14)) -> 74917 | L14: =IF($S14="","",INDEX('All reports'!$U$5:$U$249,$S14)) -> 2 | M14: =IF($S14="","",INDEX('All reports'!$Y$5:$Y$249,$S14)) -> 10 | N14: =IF($S14="","",IF(INDEX('All reports'!$N$5:$N$249,$S14)="","",INDEX('All reports'!$N$5:$N$249,$S14))) -> Exact | O14: =IF($S14="","",COUNTIF('All reports'!$M$5:$M$249,INDEX('All reports'!$M$5:$M$249,$S14))-1) -> 0 | P14: =IFERROR(HYPERLINK(INDEX('All reports'!$L$5:$L$249,$S14),"Open report"),"") -> Open report | Q14: =IFERROR(HYPERLINK(INDEX('QC listings'!$H$5:$H$200,MATCH(INDEX('All reports'!$M$5:$M$249,$S14),'QC listings'!$A$5:$A$200,0)),"Open listing"),"") -> Open listing | R14: =IF($S14="","",INDEX('All reports'!$AC$5:$AC$249,$S14)) -> Link out; Trustified's written licence needed to display the report | S14: =IFERROR(MATCH($A14,'All reports'!$AA$5:$AA$249,0),"") -> 33
A15: 11 | B15: =IF($S15="","",INDEX('All reports'!$B$5:$B$249,$S15)) -> Amul | C15: =IF($S15="","",INDEX('All reports'!$C$5:$C$249,$S15)) -> Butter | D15: =IF($S15="","",INDEX('All reports'!$E$5:$E$249,$S15)) -> Butter, paneer & cheese | E15: =IF($S15="","",INDEX('All reports'!$F$5:$F$249,$S15)) -> Passed | F15: =IF($S15="","",IF(INDEX('All reports'!$G$5:$G$249,$S15)="","",INDEX('All reports'!$G$5:$G$249,$S15))) -> 45746 | G15: =IF($S15="","",INDEX('All reports'!$I$5:$I$249,$S15)) -> Eurofins | H15: =IF($S15="","",IF(INDEX('All reports'!$H$5:$H$249,$S15)="","",INDEX('All reports'!$H$5:$H$249,$S15))) -> SAN3211 | I15: =IF($S15="","",INDEX('All reports'!$J$5:$J$249,$S15)) -> Trustified Pass/Fail | J15: =IF($S15="","",SUBSTITUTE(TRIM(IF(INDEX('All reports'!$O$5:$O$249,$S15)="Y","Blinkit",IF(INDEX('All reports'!$O$5:$O$249,$S15)="?","Blinkit?",""))&" "&IF(INDEX('All reports'!$P$5:$P$249,$S15)="Y","Zepto",IF(INDEX('All reports'!$P$5:$P$249,$S15)="?","Zepto?",""))&" "&IF(INDEX('All reports'!$Q$5:$Q$249,$S15)="Y","Instamart",IF(INDEX('All reports'!$Q$5:$Q$249,$S15)="?","Instamart?",""))&" "&IF(INDEX('All reports'!$R$5:$R$249,$S15)="Y","BigBasket",IF(INDEX('All reports'!$R$5:$R$249,$S15)="?","BigBasket?","")))," "," · ")) -> Blinkit · Zepto · Instamart? | K15: =IF($S15="","",INDEX('All reports'!$T$5:$T$249,$S15)) -> 144000 | L15: =IF($S15="","",INDEX('All reports'!$U$5:$U$249,$S15)) -> 3 | M15: =IF($S15="","",INDEX('All reports'!$Y$5:$Y$249,$S15)) -> 9 | N15: =IF($S15="","",IF(INDEX('All reports'!$N$5:$N$249,$S15)="","",INDEX('All reports'!$N$5:$N$249,$S15))) -> Exact | O15: =IF($S15="","",COUNTIF('All reports'!$M$5:$M$249,INDEX('All reports'!$M$5:$M$249,$S15))-1) -> 0 | P15: =IFERROR(HYPERLINK(INDEX('All reports'!$L$5:$L$249,$S15),"Open report"),"") -> Open report | Q15: =IFERROR(HYPERLINK(INDEX('QC listings'!$H$5:$H$200,MATCH(INDEX('All reports'!$M$5:$M$249,$S15),'QC listings'!$A$5:$A$200,0)),"Open listing"),"") -> Open listing | R15: =IF($S15="","",INDEX('All reports'!$AC$5:$AC$249,$S15)) -> Link out; Trustified's written licence needed to display the report | S15: =IFERROR(MATCH($A15,'All reports'!$AA$5:$AA$249,0),"") -> 20
A16: 12 | B16: =IF($S16="","",INDEX('All reports'!$B$5:$B$249,$S16)) -> India Gate | C16: =IF($S16="","",INDEX('All reports'!$C$5:$C$249,$S16)) -> Feast Rozzana Basmati Rice | D16: =IF($S16="","",INDEX('All reports'!$E$5:$E$249,$S16)) -> Atta, rice & salt | E16: =IF($S16="","",INDEX('All reports'!$F$5:$F$249,$S16)) -> Failed | F16: =IF($S16="","",IF(INDEX('All reports'!$G$5:$G$249,$S16)="","",INDEX('All reports'!$G$5:$G$249,$S16))) -> 46103 | G16: =IF($S16="","",INDEX('All reports'!$I$5:$I$249,$S16)) -> Eurofins | H16: =IF($S16="","",IF(INDEX('All reports'!$H$5:$H$249,$S16)="","",INDEX('All reports'!$H$5:$H$249,$S16))) -> BW52E24400 | I16: =IF($S16="","",INDEX('All reports'!$J$5:$J$249,$S16)) -> Trustified Pass/Fail | J16: =IF($S16="","",SUBSTITUTE(TRIM(IF(INDEX('All reports'!$O$5:$O$249,$S16)="Y","Blinkit",IF(INDEX('All reports'!$O$5:$O$249,$S16)="?","Blinkit?",""))&" "&IF(INDEX('All reports'!$P$5:$P$249,$S16)="Y","Zepto",IF(INDEX('All reports'!$P$5:$P$249,$S16)="?","Zepto?",""))&" "&IF(INDEX('All reports'!$Q$5:$Q$249,$S16)="Y","Instamart",IF(INDEX('All reports'!$Q$5:$Q$249,$S16)="?","Instamart?",""))&" "&IF(INDEX('All reports'!$R$5:$R$249,$S16)="Y","BigBasket",IF(INDEX('All reports'!$R$5:$R$249,$S16)="?","BigBasket?","")))," "," · ")) -> Zepto · Instamart · BigBasket | K16: =IF($S16="","",INDEX('All reports'!$T$5:$T$249,$S16)) -> 23064 | L16: =IF($S16="","",INDEX('All reports'!$U$5:$U$249,$S16)) -> 2 | M16: =IF($S16="","",INDEX('All reports'!$Y$5:$Y$249,$S16)) -> 9 | N16: =IF($S16="","",IF(INDEX('All reports'!$N$5:$N$249,$S16)="","",INDEX('All reports'!$N$5:$N$249,$S16))) -> Exact | O16: =IF($S16="","",COUNTIF('All reports'!$M$5:$M$249,INDEX('All reports'!$M$5:$M$249,$S16))-1) -> 0 | P16: =IFERROR(HYPERLINK(INDEX('All reports'!$L$5:$L$249,$S16),"Open report"),"") -> Open report | Q16: =IFERROR(HYPERLINK(INDEX('QC listings'!$H$5:$H$200,MATCH(INDEX('All reports'!$M$5:$M$249,$S16),'QC listings'!$A$5:$A$200,0)),"Open listing"),"") -> Open listing | R16: =IF($S16="","",INDEX('All reports'!$AC$5:$AC$249,$S16)) -> Link out; licence needed to display; run the PRD publication gate first (negative verdict) | S16: =IFERROR(MATCH($A16,'All reports'!$AA$5:$AA$249,0),"") -> 35
... A43: 39 | B43: =IF($S43="","",INDEX('All reports'!$B$5:$B$249,$S43)) -> The Whole Truth | C43: =IF($S43="","",INDEX('All reports'!$C$5:$C$249,$S43)) -> Raw Whey Protein Isolate | D43: =IF($S43="","",INDEX('All reports'!$E$5:$E$249,$S43)) -> Whey protein | E43: =IF($S43="","",INDEX('All reports'!$F$5:$F$249,$S43)) -> Passed | F43: =IF($S43="","",IF(INDEX('All reports'!$G$5:$G$249,$S43)="","",INDEX('All reports'!$G$5:$G$249,$S43))) -> 45460 | G43: =IF($S43="","",INDEX('All reports'!$I$5:$I$249,$S43)) -> Eurofins | H43: =IF($S43="","",IF(INDEX('All reports'!$H$5:$H$249,$S43)="","",INDEX('All reports'!$H$5:$H$249,$S43))) -> TWTWIU087F2 | I43: =IF($S43="","",INDEX('All reports'!$J$5:$J$249,$S43)) -> Trustified Pass/Fail | J43: =IF($S43="","",SUBSTITUTE(TRIM(IF(INDEX('All reports'!$O$5:$O$249,$S43)="Y","Blinkit",IF(INDEX('All reports'!$O$5:$O$249,$S43)="?","Blinkit?",""))&" "&IF(INDEX('All reports'!$P$5:$P$249,$S43)="Y","Zepto",IF(INDEX('All reports'!$P$5:$P$249,$S43)="?","Zepto?",""))&" "&IF(INDEX('All reports'!$Q$5:$Q$249,$S43)="Y","Instamart",IF(INDEX('All reports'!$Q$5:$Q$249,$S43)="?","Instamart?",""))&" "&IF(INDEX('All reports'!$R$5:$R$249,$S43)="Y","BigBasket",IF(INDEX('All reports'!$R$5:$R$249,$S43)="?","BigBasket?","")))," "," · ")) -> Zepto | K43: =IF($S43="","",INDEX('All reports'!$T$5:$T$249,$S43)) -> 0 | L43: =IF($S43="","",INDEX('All reports'!$U$5:$U$249,$S43)) -> 0 | M43: =IF($S43="","",INDEX('All reports'!$Y$5:$Y$249,$S43)) -> 0.75 | N43: =IF($S43="","",IF(INDEX('All reports'!$N$5:$N$249,$S43)="","",INDEX('All reports'!$N$5:$N$249,$S43))) -> Same line | O43: =IF($S43="","",COUNTIF('All reports'!$M$5:$M$249,INDEX('All reports'!$M$5:$M$249,$S43))-1) -> 1 | P43: =IFERROR(HYPERLINK(INDEX('All reports'!$L$5:$L$249,$S43),"Open report"),"") -> Open report | Q43: =IFERROR(HYPERLINK(INDEX('QC listings'!$H$5:$H$200,MATCH(INDEX('All reports'!$M$5:$M$249,$S43),'QC listings'!$A$5:$A$200,0)),"Open listing"),"") -> Open listing | R43: =IF($S43="","",INDEX('All reports'!$AC$5:$AC$249,$S43)) -> Link out; Trustified's written licence needed to display the report | S43: =IFERROR(MATCH($A43,'All reports'!$AA$5:$AA$249,0),"") -> 168

Sheet All reports
A1: All lab-report rows (one row per published report or rating)
A2: Sources: Trustified Pass/Fail and NMR pages, The Whole Truth's batch hub, Unbox Health. Filter on any column. From 'QC key' onwards the columns are the quick-commerce overlay and scoring; weights are on the Scoring sheet.
A3: Product | F3: Lab report | M3: Quick-commerce listing check (2 Oct 2026) | S3: Demand and score | AB3: Access and notes | AE3: Helper
A4: ID | B4: Brand | C4: Product | D4: Segment | E4: Category | F4: Verdict | G4: Report date | H4: Batch tested | I4: Lab | J4: Source | K4: Unbox rating | L4: Report link | M4: QC key | N4: QC match | O4: Blinkit | P4: Zepto | Q4: Instamart | R4: BigBasket | S4: QC platforms | T4: Top ratings count | U4: Demand tier | V4: QC category | W4: Report age (months) | X4: Freshness | Y4: QC score | Z4: Primary for line | AA4: QC rank | AB4: Access | AC4: Publish route | AD4: Notes | AE4: Sort key (helper)
A5: R001 | B5: Amul | C5: Gold Milk | D5: Everyday food | E5: Milk | F5: Failed | G5: 46061 | H5: SR26DM | I5: Eurofins | J5: Trustified Pass/Fail | L5: https://www.trustified.in/passandfail/amulgoldmilk | M5: AMUL-GOLD | N5: Exact | O5: =IF($M5="","",IF(COUNTIFS('QC listings'!$A$5:$A$200,$M5,'QC listings'!$C$5:$C$200,O$4,'QC listings'!$F$5:$F$200,"Listing page")+COUNTIFS('QC listings'!$A$5:$A$200,$M5,'QC listings'!$C$5:$C$200,O$4,'QC listings'!$F$5:$F$200,"Brand page")>0,"Y",IF(COUNTIFS('QC listings'!$A$5:$A$200,$M5,'QC listings'!$C$5:$C$200,O$4)>0,"?","–"))) -> Y | P5: =IF($M5="","",IF(COUNTIFS('QC listings'!$A$5:$A$200,$M5,'QC listings'!$C$5:$C$200,P$4,'QC listings'!$F$5:$F$200,"Listing page")+COUNTIFS('QC listings'!$A$5:$A$200,$M5,'QC listings'!$C$5:$C$200,P$4,'QC listings'!$F$5:$F$200,"Brand page")>0,"Y",IF(COUNTIFS('QC listings'!$A$5:$A$200,$M5,'QC listings'!$C$5:$C$200,P$4)>0,"?","–"))) -> Y | Q5: =IF($M5="","",IF(COUNTIFS('QC listings'!$A$5:$A$200,$M5,'QC listings'!$C$5:$C$200,Q$4,'QC listings'!$F$5:$F$200,"Listing page")+COUNTIFS('QC listings'!$A$5:$A$200,$M5,'QC listings'!$C$5:$C$200,Q$4,'QC listings'!$F$5:$F$200,"Brand page")>0,"Y",IF(COUNTIFS('QC listings'!$A$5:$A$200,$M5,'QC listings'!$C$5:$C$200,Q$4)>0,"?","–"))) -> – | R5: =IF($M5="","",IF(COUNTIFS('QC listings'!$A$5:$A$200,$M5,'QC listings'!$C$5:$C$200,R$4,'QC listings'!$F$5:$F$200,"Listing page")+COUNTIFS('QC listings'!$A$5:$A$200,$M5,'QC listings'!$C$5:$C$200,R$4,'QC listings'!$F$5:$F$200,"Brand page")>0,"Y",IF(COUNTIFS('QC listings'!$A$5:$A$200,$M5,'QC listings'!$C$5:$C$200,R$4)>0,"?","–"))) -> Y | S5: =IF($M5="","",COUNTIF(O5:R5,"Y")) -> 3 | T5: =IF($M5="","",SUMPRODUCT(MAX(('QC listings'!$A$5:$A$200=$M5)*'QC listings'!$E$5:$E$200))) -> 1581833 | U5: =IF($M5="","",IF(T5>=Scoring!$B$11,3,IF(T5>=Scoring!$B$10,2,IF(T5>=Scoring!$B$9,1,0)))) -> 3 | V5: =IFERROR(INDEX(Scoring!$B$27:$B$56,MATCH($E5,Scoring!$A$27:$A$56,0)),0) -> 1 | W5: =IF($G5="","",ROUND((Scoring!$B$5-$G5)/30.4375,1)) -> 7.8 | X5: =IF($F5="Expired",Scoring!$B$18,IF($G5="",Scoring!$B$17,IF(W5<=Scoring!$B$12,Scoring!$B$13,IF(W5<=Scoring!$B$14,Scoring!$B$15,Scoring!$B$16)))) -> 2 | Y5: =IF($M5="","",ROUND((S5*Scoring!$B$6+U5*Scoring!$B$7)*IFERROR(INDEX(Scoring!$B$22:$B$24,MATCH($N5,Scoring!$A$22:$A$24,0)),1)+V5*Scoring!$B$8+X5,2)) -> 13 | Z5: =IF($M5="","",IF(SUMPRODUCT(($M$5:$M$249=$M5)*($G$5:$G$249>$G5))>0,0,IF(SUMPRODUCT(($M$5:$M$249=$M5)*($G$5:$G$249=$G5)*(ROW($M$5:$M$249)<ROW($M5)))>0,0,1))) -> 1 | AA5: =IF($Z5=1,RANK($AE5,$AE$5:$AE$249,0),"") -> 2 | AB5: Open | AC5: Link out; licence needed to display; run the PRD publication gate first (negative verdict) | AD5: QC: Instamart listing not seen in my checks. | AE5: =IF($Z5=1,$Y5+$T5/1000000000-ROW()/10000000,"") -> 13.001581
A6: R002 | B6: Amul | C6: Taaza Homogenised Toned Milk | D6: Everyday food | E6: Milk | F6: Passed | G6: 46061 | H6: MAC2691 | I6: Eurofins | J6: Trustified Pass/Fail | L6: https://www.trustified.in/passandfail/amulHomogenisedmilk | M6: AMUL-TAAZA | N6: Exact | O6: =IF($M6="","",IF(COUNTIFS('QC listings'!$A$5:$A$200,$M6,'QC listings'!$C$5:$C$200,O$4,'QC listings'!$F$5:$F$200,"Listing page")+COUNTIFS('QC listings'!$A$5:$A$200,$M6,'QC listings'!$C$5:$C$200,O$4,'QC listings'!$F$5:$F$200,"Brand page")>0,"Y",IF(COUNTIFS('QC listings'!$A$5:$A$200,$M6,'QC listings'!$C$5:$C$200,O$4)>0,"?","–"))) -> Y | P6: =IF($M6="","",IF(COUNTIFS('QC listings'!$A$5:$A$200,$M6,'QC listings'!$C$5:$C$200,P$4,'QC listings'!$F$5:$F$200,"Listing page")+COUNTIFS('QC listings'!$A$5:$A$200,$M6,'QC listings'!$C$5:$C$200,P$4,'QC listings'!$F$5:$F$200,"Brand page")>0,"Y",IF(COUNTIFS('QC listings'!$A$5:$A$200,$M6,'QC listings'!$C$5:$C$200,P$4)>0,"?","–"))) -> Y | Q6: =IF($M6="","",IF(COUNTIFS('QC listings'!$A$5:$A$200,$M6,'QC listings'!$C$5:$C$200,Q$4,'QC listings'!$F$5:$F$200,"Listing page")+COUNTIFS('QC listings'!$A$5:$A$200,$M6,'QC listings'!$C$5:$C$200,Q$4,'QC listings'!$F$5:$F$200,"Brand page")>0,"Y",IF(COUNTIFS('QC listings'!$A$5:$A$200,$M6,'QC listings'!$C$5:$C$200,Q$4)>0,"?","–"))) -> – | R6: =IF($M6="","",IF(COUNTIFS('QC listings'!$A$5:$A$200,$M6,'QC listings'!$C$5:$C$200,R$4,'QC listings'!$F$5:$F$200,"Listing page")+COUNTIFS('QC listings'!$A$5:$A$200,$M6,'QC listings'!$C$5:$C$200,R$4,'QC listings'!$F$5:$F$200,"Brand page")>0,"Y",IF(COUNTIFS('QC listings'!$A$5:$A$200,$M6,'QC listings'!$C$5:$C$200,R$4)>0,"?","–"))) -> Y | S6: =IF($M6="","",COUNTIF(O6:R6,"Y")) -> 3 | T6: =IF($M6="","",SUMPRODUCT(MAX(('QC listings'!$A$5:$A$200=$M6)*'QC listings'!$E$5:$E$200))) -> 1214721 | U6: =IF($M6="","",IF(T6>=Scoring!$B$11,3,IF(T6>=Scoring!$B$10,2,IF(T6>=Scoring!$B$9,1,0)))) -> 3 | V6: =IFERROR(INDEX(Scoring!$B$27:$B$56,MATCH($E6,Scoring!$A$27:$A$56,0)),0) -> 1 | W6: =IF($G6="","",ROUND((Scoring!$B$5-$G6)/30.4375,1)) -> 7.8 | X6: =IF($F6="Expired",Scoring!$B$18,IF($G6="",Scoring!$B$17,IF(W6<=Scoring!$B$12,Scoring!$B$13,IF(W6<=Scoring!$B$14,Scoring!$B$15,Scoring!$B$16)))) -> 2 | Y6: =IF($M6="","",ROUND((S6*Scoring!$B$6+U6*Scoring!$B$7)*IFERROR(INDEX(Scoring!$B$22:$B$24,MATCH($N6,Scoring!$A$22:$A$24,0)),1)+V6*Scoring!$B$8+X6,2)) -> 13 | Z6: =IF($M6="","",IF(SUMPRODUCT(($M$5:$M$249=$M6)*($G$5:$G$249>$G6))>0,0,IF(SUMPRODUCT(($M$5:$M$249=$M6)*($G$5:$G$249=$G6)*(ROW($M$5:$M$249)<ROW($M6)))>0,0,1))) -> 1 | AA6: =IF($Z6=1,RANK($AE6,$AE$5:$AE$249,0),"") -> 3 | AB6: Open | AC6: Link out; Trustified's written licence needed to display the report | AD6: QC: Instamart listing not seen in my checks. | AE6: =IF($Z6=1,$Y6+$T6/1000000000-ROW()/10000000,"") -> 13.001214
A7: R003 | B7: Amul | C7: Taaza Milky Milk | D7: Everyday food | E7: Milk | F7: Failed | G7: 46061 | H7: SR07FM1228 | I7: Eurofins | J7: Trustified Pass/Fail | L7: https://www.trustified.in/passandfail/amultaazamilk | O7: =IF($M7="","",IF(COUNTIFS('QC listings'!$A$5:$A$200,$M7,'QC listings'!$C$5:$C$200,O$4,'QC listings'!$F$5:$F$200,"Listing page")+COUNTIFS('QC listings'!$A$5:$A$200,$M7,'QC listings'!$C$5:$C$200,O$4,'QC listings'!$F$5:$F$200,"Brand page")>0,"Y",IF(COUNTIFS('QC listings'!$A$5:$A$200,$M7,'QC listings'!$C$5:$C$200,O$4)>0,"?","–"))) | P7: =IF($M7="","",IF(COUNTIFS('QC listings'!$A$5:$A$200,$M7,'QC listings'!$C$5:$C$200,P$4,'QC listings'!$F$5:$F$200,"Listing page")+COUNTIFS('QC listings'!$A$5:$A$200,$M7,'QC listings'!$C$5:$C$200,P$4,'QC listings'!$F$5:$F$200,"Brand page")>0,"Y",IF(COUNTIFS('QC listings'!$A$5:$A$200,$M7,'QC listings'!$C$5:$C$200,P$4)>0,"?","–"))) | Q7: =IF($M7="","",IF(COUNTIFS('QC listings'!$A$5:$A$200,$M7,'QC listings'!$C$5:$C$200,Q$4,'QC listings'!$F$5:$F$200,"Listing page")+COUNTIFS('QC listings'!$A$5:$A$200,$M7,'QC listings'!$C$5:$C$200,Q$4,'QC listings'!$F$5:$F$200,"Brand page")>0,"Y",IF(COUNTIFS('QC listings'!$A$5:$A$200,$M7,'QC listings'!$C$5:$C$200,Q$4)>0,"?","–"))) | R7: =IF($M7="","",IF(COUNTIFS('QC listings'!$A$5:$A$200,$M7,'QC listings'!$C$5:$C$200,R$4,'QC listings'!$F$5:$F$200,"Listing page")+COUNTIFS('QC listings'!$A$5:$A$200,$M7,'QC listings'!$C$5:$C$200,R$4,'QC listings'!$F$5:$F$200,"Brand page")>0,"Y",IF(COUNTIFS('QC listings'!$A$5:$A$200,$M7,'QC listings'!$C$5:$C$200,R$4)>0,"?","–"))) | S7: =IF($M7="","",COUNTIF(O7:R7,"Y")) | T7: =IF($M7="","",SUMPRODUCT(MAX(('QC listings'!$A$5:$A$200=$M7)*'QC listings'!$E$5:$E$200))) | U7: =IF($M7="","",IF(T7>=Scoring!$B$11,3,IF(T7>=Scoring!$B$10,2,IF(T7>=Scoring!$B$9,1,0)))) | V7: =IFERROR(INDEX(Scoring!$B$27:$B$56,MATCH($E7,Scoring!$A$27:$A$56,0)),0) -> 1 | W7: =IF($G7="","",ROUND((Scoring!$B$5-$G7)/30.4375,1)) -> 7.8 | X7: =IF($F7="Expired",Scoring!$B$18,IF($G7="",Scoring!$B$17,IF(W7<=Scoring!$B$12,Scoring!$B$13,IF(W7<=Scoring!$B$14,Scoring!$B$15,Scoring!$B$16)))) -> 2 | Y7: =IF($M7="","",ROUND((S7*Scoring!$B$6+U7*Scoring!$B$7)*IFERROR(INDEX(Scoring!$B$22:$B$24,MATCH($N7,Scoring!$A$22:$A$24,0)),1)+V7*Scoring!$B$8+X7,2)) | Z7: =IF($M7="","",IF(SUMPRODUCT(($M$5:$M$249=$M7)*($G$5:$G$249>$G7))>0,0,IF(SUMPRODUCT(($M$5:$M$249=$M7)*($G$5:$G$249=$G7)*(ROW($M$5:$M$249)<ROW($M7)))>0,0,1))) | AA7: =IF($Z7=1,RANK($AE7,$AE$5:$AE$249,0),"") | AB7: Open | AC7: Link out; licence needed to display; run the PRD publication gate first (negative verdict) | AE7: =IF($Z7=1,$Y7+$T7/1000000000-ROW()/10000000,"")
A8: R004 | B8: Country Delight | C8: Cow Milk | D8: Everyday food | E8: Milk | F8: Failed | G8: 46061 | H8: DJCMG | I8: Eurofins | J8: Trustified Pass/Fail | L8: https://www.trustified.in/passandfail/countrydelightmilk | M8: CD-COW | N8: Exact | O8: =IF($M8="","",IF(COUNTIFS('QC listings'!$A$5:$A$200,$M8,'QC listings'!$C$5:$C$200,O$4,'QC listings'!$F$5:$F$200,"Listing page")+COUNTIFS('QC listings'!$A$5:$A$200,$M8,'QC listings'!$C$5:$C$200,O$4,'QC listings'!$F$5:$F$200,"Brand page")>0,"Y",IF(COUNTIFS('QC listings'!$A$5:$A$200,$M8,'QC listings'!$C$5:$C$200,O$4)>0,"?","–"))) -> Y | P8: =IF($M8="","",IF(COUNTIFS('QC listings'!$A$5:$A$200,$M8,'QC listings'!$C$5:$C$200,P$4,'QC listings'!$F$5:$F$200,"Listing page")+COUNTIFS('QC listings'!$A$5:$A$200,$M8,'QC listings'!$C$5:$C$200,P$4,'QC listings'!$F$5:$F$200,"Brand page")>0,"Y",IF(COUNTIFS('QC listings'!$A$5:$A$200,$M8,'QC listings'!$C$5:$C$200,P$4)>0,"?","–"))) -> Y | Q8: =IF($M8="","",IF(COUNTIFS('QC listings'!$A$5:$A$200,$M8,'QC listings'!$C$5:$C$200,Q$4,'QC listings'!$F$5:$F$200,"Listing page")+COUNTIFS('QC listings'!$A$5:$A$200,$M8,'QC listings'!$C$5:$C$200,Q$4,'QC listings'!$F$5:$F$200,"Brand page")>0,"Y",IF(COUNTIFS('QC listings'!$A$5:$A$200,$M8,'QC listings'!$C$5:$C$200,Q$4)>0,"?","–"))) -> Y | R8: =IF($M8="","",IF(COUNTIFS('QC listings'!$A$5:$A$200,$M8,'QC listings'!$C$5:$C$200,R$4,'QC listings'!$F$5:$F$200,"Listing page")+COUNTIFS('QC listings'!$A$5:$A$200,$M8,'QC listings'!$C$5:$C$200,R$4,'QC listings'!$F$5:$F$200,"Brand page")>0,"Y",IF(COUNTIFS('QC listings'!$A$5:$A$200,$M8,'QC listings'!$C$5:$C$200,R$4)>0,"?","–"))) -> – | S8: =IF($M8="","",COUNTIF(O8:R8,"Y")) -> 3 | T8: =IF($M8="","",SUMPRODUCT(MAX(('QC listings'!$A$5:$A$200=$M8)*'QC listings'!$E$5:$E$200))) -> 13966 | U8: =IF($M8="","",IF(T8>=Scoring!$B$11,3,IF(T8>=Scoring!$B$10,2,IF(T8>=Scoring!$B$9,1,0)))) -> 2 | V8: =IFERROR(INDEX(Scoring!$B$27:$B$56,MATCH($E8,Scoring!$A$27:$A$56,0)),0) -> 1 | W8: =IF($G8="","",ROUND((Scoring!$B$5-$G8)/30.4375,1)) -> 7.8 | X8: =IF($F8="Expired",Scoring!$B$18,IF($G8="",Scoring!$B$17,IF(W8<=Scoring!$B$12,Scoring!$B$13,IF(W8<=Scoring!$B$14,Scoring!$B$15,Scoring!$B$16)))) -> 2 | Y8: =IF($M8="","",ROUND((S8*Scoring!$B$6+U8*Scoring!$B$7)*IFERROR(INDEX(Scoring!$B$22:$B$24,MATCH($N8,Scoring!$A$22:$A$24,0)),1)+V8*Scoring!$B$8+X8,2)) -> 11 | Z8: =IF($M8="","",IF(SUMPRODUCT(($M$5:$M$249=$M8)*($G$5:$G$249>$G8))>0,0,IF(SUMPRODUCT(($M$5:$M$249=$M8)*($G$5:$G$249=$G8)*(ROW($M$5:$M$249)<ROW($M8)))>0,0,1))) -> 1 | AA8: =IF($Z8=1,RANK($AE8,$AE$5:$AE$249,0),"") -> 8 | AB8: Open | AC8: Link out; licence needed to display; run the PRD publication gate first (negative verdict) | AD8: QC: BigBasket listing not seen in my checks. | AE8: =IF($Z8=1,$Y8+$T8/1000000000-ROW()/10000000,"") -> 11.000013
A9: R005 | B9: Mother Dairy | C9: Cow Milk | D9: Everyday food | E9: Milk | F9: Failed | G9: 46061 | H9: (05)05NOV25SZ5M | I9: Eurofins | J9: Trustified Pass/Fail | L9: https://www.trustified.in/passandfail/motherdairymilk | M9: MD-COW | N9: Exact | O9: =IF($M9="","",IF(COUNTIFS('QC listings'!$A$5:$A$200,$M9,'QC listings'!$C$5:$C$200,O$4,'QC listings'!$F$5:$F$200,"Listing page")+COUNTIFS('QC listings'!$A$5:$A$200,$M9,'QC listings'!$C$5:$C$200,O$4,'QC listings'!$F$5:$F$200,"Brand page")>0,"Y",IF(COUNTIFS('QC listings'!$A$5:$A$200,$M9,'QC listings'!$C$5:$C$200,O$4)>0,"?","–"))) -> Y | P9: =IF($M9="","",IF(COUNTIFS('QC listings'!$A$5:$A$200,$M9,'QC listings'!$C$5:$C$200,P$4,'QC listings'!$F$5:$F$200,"Listing page")+COUNTIFS('QC listings'!$A$5:$A$200,$M9,'QC listings'!$C$5:$C$200,P$4,'QC listings'!$F$5:$F$200,"Brand page")>0,"Y",IF(COUNTIFS('QC listings'!$A$5:$A$200,$M9,'QC listings'!$C$5:$C$200,P$4)>0,"?","–"))) -> Y | Q9: =IF($M9="","",IF(COUNTIFS('QC listings'!$A$5:$A$200,$M9,'QC listings'!$C$5:$C$200,Q$4,'QC listings'!$F$5:$F$200,"Listing page")+COUNTIFS('QC listings'!$A$5:$A$200,$M9,'QC listings'!$C$5:$C$200,Q$4,'QC listings'!$F$5:$F$200,"Brand page")>0,"Y",IF(COUNTIFS('QC listings'!$A$5:$A$200,$M9,'QC listings'!$C$5:$C$200,Q$4)>0,"?","–"))) -> Y | R9: =IF($M9="","",IF(COUNTIFS('QC listings'!$A$5:$A$200,$M9,'QC listings'!$C$5:$C$200,R$4,'QC listings'!$F$5:$F$200,"Listing page")+COUNTIFS('QC listings'!$A$5:$A$200,$M9,'QC listings'!$C$5:$C$200,R$4,'QC listings'!$F$5:$F$200,"Brand page")>0,"Y",IF(COUNTIFS('QC listings'!$A$5:$A$200,$M9,'QC listings'!$C$5:$C$200,R$4)>0,"?","–"))) -> Y | S9: =IF($M9="","",COUNTIF(O9:R9,"Y")) -> 4 | T9: =IF($M9="","",SUMPRODUCT(MAX(('QC listings'!$A$5:$A$200=$M9)*'QC listings'!$E$5:$E$200))) -> 302321 | U9: =IF($M9="","",IF(T9>=Scoring!$B$11,3,IF(T9>=Scoring!$B$10,2,IF(T9>=Scoring!$B$9,1,0)))) -> 3 | V9: =IFERROR(INDEX(Scoring!$B$27:$B$56,MATCH($E9,Scoring!$A$27:$A$56,0)),0) -> 1 | W9: =IF($G9="","",ROUND((Scoring!$B$5-$G9)/30.4375,1)) -> 7.8 | X9: =IF($F9="Expired",Scoring!$B$18,IF($G9="",Scoring!$B$17,IF(W9<=Scoring!$B$12,Scoring!$B$13,IF(W9<=Scoring!$B$14,Scoring!$B$15,Scoring!$B$16)))) -> 2 | Y9: =IF($M9="","",ROUND((S9*Scoring!$B$6+U9*Scoring!$B$7)*IFERROR(INDEX(Scoring!$B$22:$B$24,MATCH($N9,Scoring!$A$22:$A$24,0)),1)+V9*Scoring!$B$8+X9,2)) -> 14 | Z9: =IF($M9="","",IF(SUMPRODUCT(($M$5:$M$249=$M9)*($G$5:$G$249>$G9))>0,0,IF(SUMPRODUCT(($M$5:$M$249=$M9)*($G$5:$G$249=$G9)*(ROW($M$5:$M$249)<ROW($M9)))>0,0,1))) -> 1 | AA9: =IF($Z9=1,RANK($AE9,$AE$5:$AE$249,0),"") -> 1 | AB9: Open | AC9: Link out; licence needed to display; run the PRD publication gate first (negative verdict) | AE9: =IF($Z9=1,$Y9+$T9/1000000000-ROW()/10000000,"") -> 14.000301
A10: R006 | B10: Amul | C10: Masti Dahi | D10: Everyday food | E10: Curd & yoghurt | F10: Failed | G10: 46026 | H10: SR04CM | I10: Eurofins | J10: Trustified Pass/Fail | L10: https://www.trustified.in/passandfail/mastidahipouch | M10: AMUL-DAHI-POUCH | N10: Exact | O10: =IF($M10="","",IF(COUNTIFS('QC listings'!$A$5:$A$200,$M10,'QC listings'!$C$5:$C$200,O$4,'QC listings'!$F$5:$F$200,"Listing page")+COUNTIFS('QC listings'!$A$5:$A$200,$M10,'QC listings'!$C$5:$C$200,O$4,'QC listings'!$F$5:$F$200,"Brand page")>0,"Y",IF(COUNTIFS('QC listings'!$A$5:$A$200,$M10,'QC listings'!$C$5:$C$200,O$4)>0,"?","–"))) -> Y | P10: =IF($M10="","",IF(COUNTIFS('QC listings'!$A$5:$A$200,$M10,'QC listings'!$C$5:$C$200,P$4,'QC listings'!$F$5:$F$200,"Listing page")+COUNTIFS('QC listings'!$A$5:$A$200,$M10,'QC listings'!$C$5:$C$200,P$4,'QC listings'!$F$5:$F$200,"Brand page")>0,"Y",IF(COUNTIFS('QC listings'!$A$5:$A$200,$M10,'QC listings'!$C$5:$C$200,P$4)>0,"?","–"))) -> – | Q10: =IF($M10="","",IF(COUNTIFS('QC listings'!$A$5:$A$200,$M10,'QC listings'!$C$5:$C$200,Q$4,'QC listings'!$F$5:$F$200,"Listing page")+COUNTIFS('QC listings'!$A$5:$A$200,$M10,'QC listings'!$C$5:$C$200,Q$4,'QC listings'!$F$5:$F$200,"Brand page")>0,"Y",IF(COUNTIFS('QC listings'!$A$5:$A$200,$M10,'QC listings'!$C$5:$C$200,Q$4)>0,"?","–"))) -> – | R10: =IF($M10="","",IF(COUNTIFS('QC listings'!$A$5:$A$200,$M10,'QC listings'!$C$5:$C$200,R$4,'QC listings'!$F$5:$F$200,"Listing page")+COUNTIFS('QC listings'!$A$5:$A$200,$M10,'QC listings'!$C$5:$C$200,R$4,'QC listings'!$F$5:$F$200,"Brand page")>0,"Y",IF(COUNTIFS('QC listings'!$A$5:$A$200,$M10,'QC listings'!$C$5:$C$200,R$4)>0,"?","–"))) -> – | S10: =IF($M10="","",COUNTIF(O10:R10,"Y")) -> 1 | T10: =IF($M10="","",SUMPRODUCT(MAX(('QC listings'!$A$5:$A$200=$M10)*'QC listings'!$E$5:$E$200))) -> 660000 | U10: =IF($M10="","",IF(T10>=Scoring!$B$11,3,IF(T10>=Scoring!$B$10,2,IF(T10>=Scoring!$B$9,1,0)))) -> 3 | V10: =IFERROR(INDEX(Scoring!$B$27:$B$56,MATCH($E10,Scoring!$A$27:$A$56,0)),0) -> 1 | W10: =IF($G10="","",ROUND((Scoring!$B$5-$G10)/30.4375,1)) -> 8.9 | X10: =IF($F10="Expired",Scoring!$B$18,IF($G10="",Scoring!$B$17,IF(W10<=Scoring!$B$12,Scoring!$B$13,IF(W10<=Scoring!$B$14,Scoring!$B$15,Scoring!$B$16)))) -> 2 | Y10: =IF($M10="","",ROUND((S10*Scoring!$B$6+U10*Scoring!$B$7)*IFERROR(INDEX(Scoring!$B$22:$B$24,MATCH($N10,Scoring!$A$22:$A$24,0)),1)+V10*Scoring!$B$8+X10,2)) -> 11 | Z10: =IF($M10="","",IF(SUMPRODUCT(($M$5:$M$249=$M10)*($G$5:$G$249>$G10))>0,0,IF(SUMPRODUCT(($M$5:$M$249=$M10)*($G$5:$G$249=$G10)*(ROW($M$5:$M$249)<ROW($M10)))>0,0,1))) -> 1 | AA10: =IF($Z10=1,RANK($AE10,$AE$5:$AE$249,0),"") -> 5 | AB10: Open | AC10: Link out; licence needed to display; run the PRD publication gate first (negative verdict) | AD10: QC: Blinkit card shows '6.6 lac'; read as 660,000 ratings (assumed). Other platforms not checked. | AE10: =IF($Z10=1,$Y10+$T10/1000000000-ROW()/10000000,"") -> 11.000659
A11: R007 | B11: Amul | C11: Masti Dahi Cup | D11: Everyday food | E11: Curd & yoghurt | F11: Passed | G11: 46026 | H11: MPC 338/01 | I11: Eurofins | J11: Trustified Pass/Fail | L11: https://www.trustified.in/passandfail/mastidahicup | M11: AMUL-DAHI-CUP | N11: Exact | O11: =IF($M11="","",IF(COUNTIFS('QC listings'!$A$5:$A$200,$M11,'QC listings'!$C$5:$C$200,O$4,'QC listings'!$F$5:$F$200,"Listing page")+COUNTIFS('QC listings'!$A$5:$A$200,$M11,'QC listings'!$C$5:$C$200,O$4,'QC listings'!$F$5:$F$200,"Brand page")>0,"Y",IF(COUNTIFS('QC listings'!$A$5:$A$200,$M11,'QC listings'!$C$5:$C$200,O$4)>0,"?","–"))) -> – | P11: =IF($M11="","",IF(COUNTIFS('QC listings'!$A$5:$A$200,$M11,'QC listings'!$C$5:$C$200,P$4,'QC listings'!$F$5:$F$200,"Listing page")+COUNTIFS('QC listings'!$A$5:$A$200,$M11,'QC listings'!$C$5:$C$200,P$4,'QC listings'!$F$5:$F$200,"Brand page")>0,"Y",IF(COUNTIFS('QC listings'!$A$5:$A$200,$M11,'QC listings'!$C$5:$C$200,P$4)>0,"?","–"))) -> Y | Q11: =IF($M11="","",IF(COUNTIFS('QC listings'!$A$5:$A$200,$M11,'QC listings'!$C$5:$C$200,Q$4,'QC listings'!$F$5:$F$200,"Listing page")+COUNTIFS('QC listings'!$A$5:$A$200,$M11,'QC listings'!$C$5:$C$200,Q$4,'QC listings'!$F$5:$F$200,"Brand page")>0,"Y",IF(COUNTIFS('QC listings'!$A$5:$A$200,$M11,'QC listings'!$C$5:$C$200,Q$4)>0,"?","–"))) -> – | R11: =IF($M11="","",IF(COUNTIFS('QC listings'!$A$5:$A$200,$M11,'QC listings'!$C$5:$C$200,R$4,'QC listings'!$F$5:$F$200,"Listing page")+COUNTIFS('QC listings'!$A$5:$A$200,$M11,'QC listings'!$C$5:$C$200,R$4,'QC listings'!$F$5:$F$200,"Brand page")>0,"Y",IF(COUNTIFS('QC listings'!$A$5:$A$200,$M11,'QC listings'!$C$5:$C$200,R$4)>0,"?","–"))) -> Y | S11: =IF($M11="","",COUNTIF(O11:R11,"Y")) -> 2 | T11: =IF($M11="","",SUMPRODUCT(MAX(('QC listings'!$A$5:$A$200=$M11)*'QC listings'!$E$5:$E$200))) -> 103152 | U11: =IF($M11="","",IF(T11>=Scoring!$B$11,3,IF(T11>=Scoring!$B$10,2,IF(T11>=Scoring!$B$9,1,0)))) -> 3 | V11: =IFERROR(INDEX(Scoring!$B$27:$B$56,MATCH($E11,Scoring!$A$27:$A$56,0)),0) -> 1 | W11: =IF($G11="","",ROUND((Scoring!$B$5-$G11)/30.4375,1)) -> 8.9 | X11: =IF($F11="Expired",Scoring!$B$18,IF($G11="",Scoring!$B$17,IF(W11<=Scoring!$B$12,Scoring!$B$13,IF(W11<=Scoring!$B$14,Scoring!$B$15,Scoring!$B$16)))) -> 2 | Y11: =IF($M11="","",ROUND((S11*Scoring!$B$6+U11*Scoring!$B$7)*IFERROR(INDEX(Scoring!$B$22:$B$24,MATCH($N11,Scoring!$A$22:$A$24,0)),1)+V11*Scoring!$B$8+X11,2)) -> 12 | Z11: =IF($M11="","",IF(SUMPRODUCT(($M$5:$M$249=$M11)*($G$5:$G$249>$G11))>0,0,IF(SUMPRODUCT(($M$5:$M$249=$M11)*($G$5:$G$249=$G11)*(ROW($M$5:$M$249)<ROW($M11)))>0,0,1))) -> 1 | AA11: =IF($Z11=1,RANK($AE11,$AE$5:$AE$249,0),"") -> 4 | AB11: Open | AC11: Link out; Trustified's written licence needed to display the report | AD11: QC: Zepto listing seen is a tub, not the cup pack. Blinkit and Instamart not seen. | AE11: =IF($Z11=1,$Y11+$T11/1000000000-ROW()/10000000,"") -> 12.000102
A12: R008 | B12: Epigamia | C12: Turbo 50 g | D12: Everyday food | E12: Curd & yoghurt | F12: Passed | G12: 45718 | H12: J00131 | I12: Eurofins | J12: Trustified Pass/Fail | L12: https://www.trustified.in/passandfail/epigamiayoughurt50 | O12: =IF($M12="","",IF(COUNTIFS('QC listings'!$A$5:$A$200,$M12,'QC listings'!$C$5:$C$200,O$4,'QC listings'!$F$5:$F$200,"Listing page")+COUNTIFS('QC listings'!$A$5:$A$200,$M12,'QC listings'!$C$5:$C$200,O$4,'QC listings'!$F$5:$F$200,"Brand page")>0,"Y",IF(COUNTIFS('QC listings'!$A$5:$A$200,$M12,'QC listings'!$C$5:$C$200,O$4)>0,"?","–"))) | P12: =IF($M12="","",IF(COUNTIFS('QC listings'!$A$5:$A$200,$M12,'QC listings'!$C$5:$C$200,P$4,'QC listings'!$F$5:$F$200,"Listing page")+COUNTIFS('QC listings'!$A$5:$A$200,$M12,'QC listings'!$C$5:$C$200,P$4,'QC listings'!$F$5:$F$200,"Brand page")>0,"Y",IF(COUNTIFS('QC listings'!$A$5:$A$200,$M12,'QC listings'!$C$5:$C$200,P$4)>0,"?","–"))) | Q12: =IF($M12="","",IF(COUNTIFS('QC listings'!$A$5:$A$200,$M12,'QC listings'!$C$5:$C$200,Q$4,'QC listings'!$F$5:$F$200,"Listing page")+COUNTIFS('QC listings'!$A$5:$A$200,$M12,'QC listings'!$C$5:$C$200,Q$4,'QC listings'!$F$5:$F$200,"Brand page")>0,"Y",IF(COUNTIFS('QC listings'!$A$5:$A$200,$M12,'QC listings'!$C$5:$C$200,Q$4)>0,"?","–"))) | R12: =IF($M12="","",IF(COUNTIFS('QC listings'!$A$5:$A$200,$M12,'QC listings'!$C$5:$C$200,R$4,'QC listings'!$F$5:$F$200,"Listing page")+COUNTIFS('QC listings'!$A$5:$A$200,$M12,'QC listings'!$C$5:$C$200,R$4,'QC listings'!$F$5:$F$200,"Brand page")>0,"Y",IF(COUNTIFS('QC listings'!$A$5:$A$200,$M12,'QC listings'!$C$5:$C$200,R$4)>0,"?","–"))) | S12: =IF($M12="","",COUNTIF(O12:R12,"Y")) | T12: =IF($M12="","",SUMPRODUCT(MAX(('QC listings'!$A$5:$A$200=$M12)*'QC listings'!$E$5:$E$200))) | U12: =IF($M12="","",IF(T12>=Scoring!$B$11,3,IF(T12>=Scoring!$B$10,2,IF(T12>=Scoring!$B$9,1,0)))) | V12: =IFERROR(INDEX(Scoring!$B$27:$B$56,MATCH($E12,Scoring!$A$27:$A$56,0)),0) -> 1 | W12: =IF($G12="","",ROUND((Scoring!$B$5-$G12)/30.4375,1)) -> 19 | X12: =IF($F12="Expired",Scoring!$B$18,IF($G12="",Scoring!$B$17,IF(W12<=Scoring!$B$12,Scoring!$B$13,IF(W12<=Scoring!$B$14,Scoring!$B$15,Scoring!$B$16)))) -> 1 | Y12: =IF($M12="","",ROUND((S12*Scoring!$B$6+U12*Scoring!$B$7)*IFERROR(INDEX(Scoring!$B$22:$B$24,MATCH($N12,Scoring!$A$22:$A$24,0)),1)+V12*Scoring!$B$8+X12,2)) | Z12: =IF($M12="","",IF(SUMPRODUCT(($M$5:$M$249=$M12)*($G$5:$G$249>$G12))>0,0,IF(SUMPRODUCT(($M$5:$M$249=$M12)*($G$5:$G$249=$G12)*(ROW($M$5:$M$249)<ROW($M12)))>0,0,1))) | AA12: =IF($Z12=1,RANK($AE12,$AE$5:$AE$249,0),"") | AB12: Open | AC12: Link out; Trustified's written licence needed to display the report | AE12: =IF($Z12=1,$Y12+$T12/1000000000-ROW()/10000000,"")
